Workbook

Sheet label_inventory
A1: (Child) ASIN | B1: Brand | C1: Product | D1: Size | E1: label_inventory
A2: B0BRTJGR33 | B2: TPS Plant Foods | C2: Fiddle Leaf Fig Plant Food for All Fig and Other Ficus Trees, Liquid Houseplant Fertilizer 8 oz (250mL) | D2: 8oz | E2: {=XLOOKUP(A2, production_planning!L:L, production_planning!AI:AI, "")} -> 3134
A3: B0BRTKV4TC | B3: TPS Plant Foods | C3: Liquid Plant Food for use in AeroGarden, IDOO and Hydroponic Growing Systems, Liquid Fertilizer 8 oz (250mL) | D3: 8oz | E3: {=XLOOKUP(A3, production_planning!L:L, production_planning!AI:AI, "")} -> 9627
A4: B0BRTK1P8Z | B4: TPS Plant Foods | C4: Monstera Plant Food for Monsteras and Philodendrons, Tropical Houseplant Liquid Fertilizer 8 oz (250mL) | D4: 8oz | E4: {=XLOOKUP(A4, production_planning!L:L, production_planning!AI:AI, "")} -> 5550
A5: B0C73SNJCH | B5: TPS Plant Foods | C5: Lemon Tree Fertilizer, Complete Lemon Tree Plant Food, 8 oz (250mL) | D5: 8oz | E5: {=XLOOKUP(A5, production_planning!L:L, production_planning!AI:AI, "")} -> 9073
A6: B0BRTJB518 | B6: TPS Plant Foods | C6: Indoor Plant Food, Liquid Fertilizer for Healthy Growth & Vibrant Foliage in Houseplants, by TPS Plant Foods, 8 oz (250 mL) | D6: 8oz | E6: {=XLOOKUP(A6, production_planning!L:L, production_planning!AI:AI, "")} -> 8191
A7: B0BRTJBFP7 | B7: TPS Plant Foods | C7: Orchid Plant Food for All Orchids and Acid Loving Houseplants, Promotes Growth and Blooms, Liquid Fertilizer 8 oz (250mL) | D7: 8oz | E7: {=XLOOKUP(A7, production_planning!L:L, production_planning!AI:AI, "")} -> 5979
A8: B07CX36LW8 | B8: TPS Nutrients | C8: TPS NUTRIENTS Silica Gold Plant Strength Nutrient and Supplement with Bioavailable Silicon 1 Quart (32 oz) | D8: Quart | E8: {=XLOOKUP(A8, production_planning!L:L, production_planning!AI:AI, "")} -> 4459
A9: B0C73TCVFW | B9: TPS Plant Foods | C9: Lemon Tree Fertilizer for Lemon Trees and Citrus, Liquid Plant Food, 32 oz (1 Quart) | D9: Quart | E9: {=XLOOKUP(A9, production_planning!L:L, production_planning!AI:AI, "")} -> 2970
A10: B0BRTJ4PLB | B10: TPS Plant Foods | C10: Succulent Plant Food for Succulents, Cactus, Jade and Aloe, Liquid Houseplant Fertilizer 8 oz (250mL) | D10: 8oz | E10: {=XLOOKUP(A10, production_planning!L:L, production_planning!AI:AI, "")} -> 1567
A11: B0C73S6Q23 | B11: TPS Plant Foods | C11: Citrus Fertilizer for All Citrus and Fruiting Trees, Liquid Plant Food 8 oz (250mL) | D11: 8oz | E11: {=XLOOKUP(A11, production_planning!L:L, production_planning!AI:AI, "")} -> 7337
A12: B09P2JPHZ6 | B12: TPS Nutrients | C12: TPS NUTRIENTS Billions Concentrated Microbial Root Enhancer, 100% Water-Soluble with Mycorrhizae, Bacteria and Trichoderma, 8 oz (1/2 Pound) | D12: 1/2lb | E12: {=XLOOKUP(A12, production_planning!L:L, production_planning!AI:AI, "")} -> 0
A13: B07CWQNYYC | B13: TPS Nutrients | C13: TPS NUTRIENTS Organic Cal-Mag OAC Plant Nutrient and Supplement, Plus Iron and Micronutrients 1 Quart (32 oz) | D13: Quart | E13: {=XLOOKUP(A13, production_planning!L:L, production_planning!AI:AI, "")} -> 987
... A23: B0C6R56WK1 | B23: TPS Plant Foods | C23: Bonsai Fertilizer, Liquid Plant Food for Healthy Growth & Strong Roots in All Bonsai Trees, by TPS Plant Foods, 8 oz (250 mL) | D23: 8oz | E23: {=XLOOKUP(A23, production_planning!L:L, production_planning!AI:AI, "")} -> 4551
A24: B097F8WJ3H | C24: Silica Gold Plant Strength Nutrient and Supplement with Bioavailable Silicon by TPS Nutrients, 1 Pint (16 oz) | E24: {=XLOOKUP(A24, production_planning!L:L, production_planning!AI:AI, "")}
A25: B097FF39YJ | C25: Signal Terpene Enhancer Plant Nutrient and Supplement, Flower Hardener and Increases Flavor by TPS Nutrients, 1 Pint (16 oz) | E25: {=XLOOKUP(A25, production_planning!L:L, production_planning!AI:AI, "")}
A26: B0C6R6KYGM | B26: TPS Plant Foods | C26: TPS NUTRIENTS Cactus Fertilizer for Cacti and All Desert Plants, Liquid Plant Food 8 oz (250mL) | D26: 8oz | E26: {=XLOOKUP(A26, production_planning!L:L, production_planning!AI:AI, "")} -> 1893
A27: B0C73RDD6N | B27: TPS Plant Foods | C27: Hibiscus Fertilizer for Tropical and Flowering Plants, Liquid Plant Food 8 oz (250mL) | D27: 8oz | E27: {=XLOOKUP(A27, production_planning!L:L, production_planning!AI:AI, "")} -> 3694
A28: B07CWP4MWW | B28: TPS Nutrients | C28: TPS NUTRIENTS Bloom Bud Builder & Flower Hardener Plant Nutrient and Supplement, Triggers Fast Flowering 1 Quart (32 oz) | D28: Quart | E28: {=XLOOKUP(A28, production_planning!L:L, production_planning!AI:AI, "")} -> 1910
A29: B0BRTJ6V3D | B29: TPS Plant Foods | C29: TPS NUTRIENTS Indoor Plant Food for Houseplants, Liquid Fertilizer, 32 oz (1 Quart) | D29: Quart | E29: {=XLOOKUP(A29, production_planning!L:L, production_planning!AI:AI, "")} -> 2549
A30: B09P3L4ZPN | B30: TPS Nutrients | C30: TPS NUTRIENTS Billions Concentrated Microbial Root Enhancer, 100% Water-Soluble with Mycorrhizae, Bacteria and Trichoderma, 16 oz (1 Pound) | D30: 1lb | E30: {=XLOOKUP(A30, production_planning!L:L, production_planning!AI:AI, "")} -> 0
A31: B0BRTJJ987 | B31: TPS Plant Foods | C31: Fiddle Leaf Fig Plant Food for All Fig and Other Ficus Trees, Liquid Houseplant Fertilizer, 32 oz (1 Quart) | D31: Quart | E31: {=XLOOKUP(A31, production_planning!L:L, production_planning!AI:AI, "")} -> 768
A32: B097FFWVHN | C32: Bloom Bud Builder & Flower Hardener Plant Nutrient and Supplement, Triggers Fast Flowering by TPS Nutrients, 1 Pint (16 oz) | E32: {=XLOOKUP(A32, production_planning!L:L, production_planning!AI:AI, "")}
A33: B0C73PVKDR | B33: TPS Plant Foods | C33: Plumeria Fertilizer for All Frangipani and Tropical Plants, Liquid Plant Food 8 oz (250mL) | D33: 8oz | E33: {=XLOOKUP(A33, production_planning!L:L, production_planning!AI:AI, "")} -> 4418
A34: B097J2XJNN | C34: Cal-Mag Complete, Calcium Magnesium Iron and Micronutrients Fertilizer and Supplement by TPS Nutrients, 1 Pint (16 oz) | D34: 16oz | E34: {=XLOOKUP(A34, production_planning!L:L, production_planning!AI:AI, "")}
A35: B0BRTKX9QR | B35: TPS Plant Foods | C35: Monstera Plant Food for Monsteras and Philodendrons, Tropical Houseplant Liquid Fertilizer, 32 oz (1 Quart) | D35: Quart | E35: {=XLOOKUP(A35, production_planning!L:L, production_planning!AI:AI, "")} -> 1403
A36: B0C6Q69C7K | B36: TPS Plant Foods | C36: Snake Plant Fertilizer for Snake Plants and All Sansevieria, 8 oz (250mL) | D36: 8oz | E36: {=XLOOKUP(A36, production_planning!L:L, production_planning!AI:AI, "")} -> 2014
A37: B07CWQ4PXV | B37: TPS Nutrients | C37: TPS NUTRIENTS N-Primer Nitrogen Supplement for Fast Vegetative Growth, Promotes Dark Green Leaves Quart (32 oz) | D37: Quart | E37: {=XLOOKUP(A37, production_planning!L:L, production_planning!AI:AI, "")} -> 1348
A38: B095JFK9B8 | C38: 0 | E38: {=XLOOKUP(A38, production_planning!L:L, production_planning!AI:AI, "")}
A39: B0C6Q5F2HR | B39: TPS Plant Foods | C39: Gardenia Fertilizer for Gardenias, Camellia and Rhododendron Plants, Flowering Liquid Plant Food 8 oz (250mL) | D39: 8oz | E39: {=XLOOKUP(A39, production_planning!L:L, production_planning!AI:AI, "")} -> 3890
A40: B0C73SC6S6 | B40: TPS Plant Foods | C40: Fruit Tree Fertilizer for All Fruit Trees Peach, Apple, and Pear, Liquid Plant Food, 32 oz (1 Quart) | D40: Quart | E40: {=XLOOKUP(A40, production_planning!L:L, production_planning!AI:AI, "")} -> 1739
A41: B0C6R6RL7B | B41: TPS Plant Foods | C41: TPS NUTRIENTS Air Plant Fertilizer for All Tillandsia Air Plants, Use As Foliar Spray or for Soaking, Liquid Plant Food, 32 oz (1 Quart) | D41: Quart | E41: {=XLOOKUP(A41, production_planning!L:L, production_planning!AI:AI, "")} -> 924
A42: B0C73RXR9M | B42: TPS Plant Foods | C42: TPS NUTRIENTS Tree Fertilizer for All Trees and Shrubs, Liquid Plant Food 8 oz (250mL) | D42: 8oz | E42: {=XLOOKUP(A42, production_planning!L:L, production_planning!AI:AI, "")} -> 1625
A43: B01MR9WDW7 | B43: TPS Nutrients | C43: Cal-Mag Complete, Calcium Magnesium Iron and Micronutrients Fertilizer and Supplement by TPS Nutrients, 1 Quart (32 oz) | D43: Quart | E43: {=XLOOKUP(A43, production_planning!L:L, production_planning!AI:AI, "")} -> 440
A44: B0BRTJC59Q | B44: TPS Plant Foods | C44: Herb Plant Food for All Edible Herbs, Leafy Greens and Veggies, Liquid Houseplant Fertilizer, 32 oz (1 Quart) | D44: Quart | E44: {=XLOOKUP(A44, production_planning!L:L, production_planning!AI:AI, "")} -> 402
A45: B08176NTH7 | B45: TPS Nutrients | C45: TPS NUTRIENTS One Liquid One Part Plant Nutrient from Veg to Bloom, for Lush Growth and Dense Flowers 1 Quart (32 oz) | D45: Quart | E45: {=XLOOKUP(A45, production_planning!L:L, production_planning!AI:AI, "")} -> 856
A46: B0C73TNKXQ | B46: TPS Plant Foods | C46: Fruit Tree Fertilizer for All Fruit Trees Peach, Apple, and Pear, Liquid Plant Food 8 oz (250mL) | D46: 8oz | E46: {=XLOOKUP(A46, production_planning!L:L, production_planning!AI:AI, "")} -> 279
A47: B0C73R715R | B47: TPS Plant Foods | C47: Blueberry Fertilizer for Acid Loving Fruit and Berry Gardens, Liquid Plant Food, 32 oz (1 Quart) | D47: Quart | E47: {=XLOOKUP(A47, production_planning!L:L, production_planning!AI:AI, "")} -> 2288
A48: B0C73RF7GX | B48: TPS Plant Foods | C48: TPS NUTRIENTS Tree Fertilizer for All Trees and Shrubs, Liquid Plant Food, 32 oz (1 Quart) | D48: Quart | E48: {=XLOOKUP(A48, production_planning!L:L, production_planning!AI:AI, "")} -> 1552
A49: B07CWQ2V2G | B49: TPS Nutrients | C49: TPS NUTRIENTS Signal Terpene Enhancer Plant Nutrient and Supplement, Flower Hardener and Increases Flavor, 1 Gallon (128 oz) | D49: 1 Gallon | E49: {=XLOOKUP(A49, production_planning!L:L, production_planning!AI:AI, "")} -> 247
...

Sheet production_planning
J1: Formula | N1: Formula | O1: Formula | T1: Formula | U1: Formula | V1: Formula | AB1: Formula | AC1: Formula | AE1: Formula | AF1: Formula | AH1: Formula | AI1: Formula | AJ1: Formula | AK1: Formula | AL1: Formula | AM1: Formula | AN1: Formula | AO1: Formula | AP1: Formula | AQ1: Formula | AR1: Formula | AX1: Formula | AY1: Formula | AZ1: Formula | BA1: Formula | BB1: Formula | BC1: Formula | BD1: Formula | BE1: Formula | BF1: Formula | BG1: Formula | BJ1: Formula | BK1: Formula | BO1: Formula | BP1: Formula | BQ1: Formula | BR1: Formula | BS1: Formula | BT1: Formula | BU1: Formula | BV1: Formula | BW1: Formula | BX1: Formula | BY1: Formula | BZ1: Formula | CA1: Formula | CB1: Formula | CC1: Formula | CD1: Formula | CE1: Formula | CJ1: Formula | CK1: Formula | CL1: Formula | CM1: Formula | CN1: Formula | CO1: Formula | CP1: Formula | CQ1: Formula | CR1: Formula | CS1: Formula | CT1: Formula | CU1: Formula | CV1: Formula
B2: # | C2: Release Date | D2: Act | E2: MarketPlace | F2: Brand | G2: Product | H2: Size | I2: Quantity | J2: Case Qty | K2: Sku | L2: Item # | M2: Formula | N2: # per Case | O2: Case Size | P2: Label Location | Q2: Caps | R2: Type | S2: Filter | T2: Volume (Gal) | U2: Price | V2: Total $ | W2: Status Locked | X2: Status Printed | Y2: Status Added to Production Order | Z2: Status Added to Manufacturing Plan | AA2: Note | AB2: Forecast New Products / Accelerate | AC2: 120/140 actual Days Total | AD2: 30 Days Available x Velocity | AE2: Forecast Standard Multiplier | AF2: Forecast Standard Multiplier Revenue | AG2: Label Printed | AH2: Label % of Production | AI2: Label Current Inventory | AJ2: Inventory Total Amazon Units | AK2: Inventory Total (Days) | AL2: Inventory FBA Available (Days) | AM2: Inventory Available Boxes AWD | AN2: MOVE FROM AWD (Boxes) | AO2: Inventory Inbound FBA | AP2: Shipment Pallet Qty | AQ2: Shipment Weight | AR2: Shipment Time (hrs) | AS2: Shipment TPS Shipment # | AT2: Shipment Type (AWD, FBA, Parcel) | AU2: Shipment # | AV2: Shipment Ref ID | AW2: Seven Day Over 30 Day Percentage | AX2: Sales Units Sold last 7 days | AY2: Sales Units Sold last 14 days | AZ2: Sales Units Sold last 28 days | BA2: Sales Units Sold last 42 days | BB2: Sales Units Sold last 4 months | BC2: Sales SUMMER '23 Units Sold Jun1-Sept30 2023 | BD2: Sales WINTER ' 23 Units Sold Oct1-Jan31 2023 | BE2: Sales SPRING '24 Units Sold Feb1-May31 2024 | BF2: Sales SUMMER '24 Units Sold Jun1-Sept30 2024 | BG2: Sales WINTER ' 24 Units Sold Oct1-Jan31 2024 | BH2: Vine Date | BI2: Vine Units Claimed | BJ2: 20 Weeks of Inventory(Weighted) | BK2: Label Current Inventory | BL2: Label Status | BM2: Label File | BN2: Label Size | BO2: Label Last Date Ordered | BP2: Label # to Order 12 MONTH OLDER | BQ2: Label # to Order NEW PRODUCTS | BR2: Label Days of Inventory | BS2: Label Inbound | BT2: Inventory Total In Stock $ | BU2: Inventory Days of Prime (based on 7 day sales) | BV2: Inventory Days of FBA (from Amazon) | BW2: Inventory Date Last Produced | BX2: Inventory Quantity Shipped | BY2: Inventory Available FBA | BZ2: Inventory Reserved FBA | CA2: Inventory Inbound FBA | CB2: Inventory Available AWD | CC2: Inventory Reserved AWD | CD2: Inventory Inbound AWD | CE2: Inventory AWD Outbound to FBA | CF2: MISSED AWD PRODUCTION | CG2: MISSED FBA PRODUCTION | CH2: Secondary Item# (GTIN) | CI2: Listed Name | CJ2: Product Stat Launch Date | CK2: Product Stat Age (mths) | CL2: Product Stat Expires? | CM2: Product Stat Age Category | CN2: Product Stat Product Category | CO2: Product Stat Seasonality Category | CP2: Forecast Needed Accelerating | CQ2: FBA Bandaid to 45 Days | CR2: Forecast Units Needed Multiplier | CS2: Forecast SUMMER OF DREAMS | CT2: Multiplier Auto Pull | CU2: Forecast Spring 24 | CV2: Forecast Fall/Winter 23
A3: Forecast | D3: TPS | E3: Amazon | F3: TPS Plant Foods | G3: 10-10-10 Fertilizer | H3: 8oz | I3: 0 | J3: 0 | K3: TRIPLE10GEN8OZ | L3: B0D4JHN9KK | M3: F.10-10-10 | N3: 60 | O3: 12x10x12 | P3: LBL-PLANT-001 | Q3: Aptar Pour | R3: Liquid | S3: 75 | T3: 0 | U3: 11.99 | V3: 0 | W3: FALSE | X3: FALSE | Y3: FALSE | Z3: FALSE | AB3: 120 | AC3: 0 | AD3: 0 | AE3: 60 | AF3: 719 | AH3: 0 | AI3: 2063 | AJ3: 637 | AK3: 1098 | AL3: 1005 | AM3: 0 | AN3: 0 | AO3: 0 | AP3: 0 | AQ3: 0 | AR3: 0 | AW3: 0 | AX3: 0 | AY3: 14 | AZ3: 19 | BA3: 27 | BB3: 92 | BC3: 0 | BD3: 0 | BE3: 0 | BF3: 196 | BG3: 139 | BJ3: 70 | BK3: 2063 | BL3: Current | BM3: https://drive.google.com/open?id=12kkUJSNpkStvU1iGFPHgXm0-PC4Sb91j&usp=drive_fs | BN3: 5" x 8" | BP3: 0 | BQ3: Established | BR3: 7865 | BT3: 7638 | BU3: 0 | BV3: 144 | BW3: 45896 | BX3: 420 | BY3: 583 | BZ3: 54 | CA3: 0 | CB3: 0 | CC3: 0 | CD3: 0 | CE3: 0 | CJ3: 45444 | CK3: 20 | CL3: No | CM3: Established | CN3: Garden | CO3: Seasonal | CP3: 115 | CQ3: 0 | CR3: 42 | CS3: -429 | CT3: 66.7 | CU3: 0 | CV3: 0
A4: Forecast | D4: TPS | E4: Amazon | F4: TPS Plant Foods | G4: 10-10-10 Fertilizer | H4: Quart | I4: 0 | J4: 0 | K4: TRIPLE10GEN1Q | L4: B0D4JHVBDQ | M4: F.10-10-10 | N4: 12 | O4: 13x13x10 | P4: LBL-PLANT-226 | Q4: Aptar Pour | R4: Liquid | S4: 75 | T4: 0 | U4: 24.99 | V4: 0 | W4: FALSE | X4: FALSE | Y4: FALSE | Z4: FALSE | AB4: 48 | AC4: 0 | AD4: 0 | AE4: 12 | AF4: 300 | AH4: 0 | AI4: 1577 | AJ4: 172 | AK4: 980 | AL4: 222 | AM4: 0 | AN4: 0 | AO4: 0 | AP4: 0 | AQ4: 0 | AR4: 0 | AW4: 0 | AX4: 0 | AY4: 5 | AZ4: 5 | BA4: 7 | BB4: 30 | BC4: 0 | BD4: 0 | BE4: 0 | BF4: 81 | BG4: 60 | BJ4: 22 | BK4: 1577 | BL4: Current | BM4: https://drive.google.com/open?id=12kkUJSNpkStvU1iGFPHgXm0-PC4Sb91j&usp=drive_fs | BN4: 5" x 8" | BP4: 0 | BQ4: Established | BR4: 17494 | BT4: 4298 | BU4: 0 | BV4: 66 | BW4: 46044 | BX4: 132 | BY4: 39 | BZ4: 1 | CA4: 0 | CB4: 0 | CC4: 0 | CD4: 132 | CE4: 0 | CJ4: 45444 | CK4: 20 | CL4: No | CM4: Established | CN4: Garden | CO4: Seasonal | CP4: 38 | CQ4: 0 | CR4: 11 | CS4: -96 | CT4: 66.7 | CU4: 0 | CV4: 0
A5: Forecast | D5: TPS | E5: Amazon | F5: TPS Plant Foods | G5: 10-10-10 Fertilizer | H5: 1 Gallon | I5: 0 | J5: 0 | K5: TRIPLE10GEN1G | L5: B0D4JGCSM1 | M5: F.10-10-10 | N5: 4 | O5: 13x13x13 | P5: LBL-PLANT-483 | Q5: Berry Unvented | R5: Liquid | S5: 75 | T5: 0 | U5: 49.99 | V5: 0 | W5: FALSE | X5: FALSE | Y5: FALSE | Z5: FALSE | AB5: 24 | AC5: 0 | AD5: 0 | AE5: 8 | AF5: 400 | AH5: 0 | AI5: 402 | AJ5: 66 | AK5: 853 | AL5: 246 | AM5: 0 | AN5: 0 | AO5: 0 | AP5: 0 | AQ5: 0 | AR5: 0 | AW5: 0 | AX5: 0 | AY5: 2 | AZ5: 2 | BA5: 4 | BB5: 18 | BC5: 0 | BD5: 0 | BE5: 0 | BF5: 0 | BG5: 0 | BJ5: 9 | BK5: 402 | BL5: Current | BM5: https://drive.google.com/open?id=12kkUJSNpkStvU1iGFPHgXm0-PC4Sb91j&usp=drive_fs | BN5: 5" x 8" | BP5: 0 | BQ5: Established | BR5: 9359 | BT5: 3299 | BU5: 0 | BV5: 79 | BW5: 46042 | BX5: 44 | BY5: 19 | BZ5: 3 | CA5: 0 | CB5: 0 | CC5: 0 | CD5: 44 | CE5: 0 | CJ5: 45444 | CK5: 20 | CL5: No | CM5: Established | CN5: Garden | CO5: Seasonal | CP5: 23 | CQ5: 0 | CR5: 4 | CS5: -35 | CT5: 66.7 | CU5: 0 | CV5: 0
A6: Forecast | D6: TPS | E6: Amazon | F6: TPS Plant Foods | G6: 10-10-10 Fertilizer For Plants | H6: 8oz | I6: 0 | J6: 0 | K6: TRIPLE10PLANTS8OZ | L6: B0D4JGRK2C | M6: F.10-10-10 | N6: 60 | O6: 12x10x12 | P6: LBL-PLANT-002 | Q6: Aptar Pour | R6: Liquid | S6: 75 | T6: 0 | U6: 11.99 | V6: 0 | W6: FALSE | X6: FALSE | Y6: FALSE | Z6: FALSE | AB6: 180 | AC6: 0 | AD6: 0 | AE6: 120 | AF6: 1439 | AH6: 0 | AI6: 198 | AJ6: 882 | AK6: 1110 | AL6: 107 | AM6: 0 | AN6: 0 | AO6: 0 | AP6: 0 | AQ6: 0 | AR6: 0 | AW6: 0 | AX6: 0 | AY6: 15 | AZ6: 27 | BA6: 48 | BB6: 114 | BC6: 0 | BD6: 0 | BE6: 0 | BF6: 45 | BG6: 66 | BJ6: 88 | BK6: 198 | BL6: Current | BM6: https://drive.google.com/open?id=12tnHyKPWEETodS_CBrKGGcS1NveE9Nnr&usp=drive_fs | BN6: 5" x 8" | BP6: 0 | BQ6: Established | BR6: 2348 | BT6: 10575 | BU6: 0 | BV6: 46 | BW6: 46036 | BX6: 780 | BY6: 85 | BZ6: 17 | CA6: 0 | CB6: 0 | CC6: 0 | CD6: 780 | CE6: 0 | CJ6: 45444 | CK6: 20 | CL6: No | CM6: Established | CN6: Garden | CO6: Seasonal | CP6: 143 | CQ6: 0 | CR6: 60 | CS6: -688 | CT6: 66.7 | CU6: 0 | CV6: 0
A7: Forecast | D7: TPS | E7: Amazon | F7: TPS Plant Foods | G7: 10-10-10 Fertilizer For Plants | H7: Quart | I7: 0 | J7: 0 | K7: TRIPLE10PLANTS1Q | L7: B0D4JFLDK3 | M7: F.10-10-10 | N7: 12 | O7: 13x13x10 | P7: LBL-PLANT-227 | Q7: Aptar Pour | R7: Liquid | S7: 75 | T7: 0 | U7: 24.99 | V7: 0 | W7: FALSE | X7: FALSE | Y7: FALSE | Z7: FALSE | AB7: 72 | AC7: 0 | AD7: 0 | AE7: 36 | AF7: 900 | AH7: 0 | AI7: 617 | AJ7: 135 | AK7: 336 | AL7: 304 | AM7: 0 | AN7: 0 | AO7: 0 | AP7: 0 | AQ7: 0 | AR7: 0 | AW7: 0 | AX7: 0 | AY7: 9 | AZ7: 15 | BA7: 18 | BB7: 49 | BC7: 0 | BD7: 0 | BE7: 0 | BF7: 24 | BG7: 26 | BJ7: 48 | BK7: 617 | BL7: Current | BM7: https://drive.google.com/open?id=12tnHyKPWEETodS_CBrKGGcS1NveE9Nnr&usp=drive_fs | BN7: 5" x 8" | BP7: 0 | BQ7: Established | BR7: 3246 | BT7: 3374 | BU7: 0 | BV7: 87 | BW7: 45889 | BX7: 96 | BY7: 122 | BZ7: 13 | CA7: 0 | CB7: 0 | CC7: 0 | CD7: 0 | CE7: 0 | CJ7: 45444 | CK7: 20 | CL7: No | CM7: Established | CN7: Garden | CO7: Seasonal | CP7: 61 | CQ7: 0 | CR7: 33 | CS7: -52 | CT7: 66.7 | CU7: 0 | CV7: 0
A8: Forecast | D8: TPS | E8: Amazon | F8: TPS Plant Foods | G8: 10-10-10 Fertilizer For Plants | H8: 1 Gallon | I8: 0 | J8: 0 | K8: TRIPLE10PLANTS1G | L8: B0D4JDPWX5 | M8: F.10-10-10 | N8: 4 | O8: 13x13x13 | P8: LBL-PLANT-484 | Q8: Berry Unvented | R8: Liquid | S8: 75 | T8: 0 | U8: 49.99 | V8: 0 | W8: FALSE | X8: FALSE | Y8: FALSE | Z8: FALSE | AB8: 0 | AC8: 0 | AD8: #VALUE! | AE8: No Sales | AF8: 0 | AH8: 0 | AI8: 362 | AJ8: 50 | AK8: NO SALES | AL8: NO SALES | AM8: 0 | AN8: 0 | AO8: 0 | AP8: 0 | AQ8: 0 | AR8: 0 | AW8: 0 | AX8: 0 | AY8: 0 | AZ8: 0 | BA8: 0 | BB8: 0 | BC8: 0 | BD8: 0 | BE8: 0 | BF8: 0 | BG8: 0 | BJ8: 0 | BK8: 362 | BL8: Current | BM8: https://drive.google.com/open?id=12tnHyKPWEETodS_CBrKGGcS1NveE9Nnr&usp=drive_fs | BN8: 5" x 8" | BP8: 0 | BQ8: Established | BR8: NO SALES | BT8: 2500 | BU8: 0 | BV8: 0 | BW8: 45918 | BX8: 40 | BY8: 50 | BZ8: 0 | CA8: 0 | CB8: 0 | CC8: 0 | CD8: 0 | CE8: 0 | CJ8: 45444 | CK8: 20 | CL8: No | CM8: Established | CN8: Garden | CO8: Seasonal | CP8: 0 | CQ8: 0 | CR8: No Sales | CS8: -50 | CT8: 66.7 | CU8: 0 | CV8: 0
A9: Forecast | D9: TPS | E9: Amazon | F9: TPS Plant Foods | G9: 10-10-10 Fertilizer For Trees | H9: Quart | I9: 0 | J9: 0 | K9: TRIPLE10TREE1Q | L9: B0D4JGZRBH | M9: F.10-10-10 | N9: 12 | O9: 13x13x10 | P9: LBL-PLANT-228 | Q9: Aptar Pour | R9: Liquid | S9: 75 | T9: 0 | U9: 24.99 | V9: 0 | W9: FALSE | X9: FALSE | Y9: FALSE | Z9: FALSE | AB9: 276 | AC9: 0 | AD9: 0 | AE9: 96 | AF9: 2399 | AH9: 0 | AI9: 1209 | AJ9: 1131 | AK9: 914 | AL9: 439 | AM9: 0 | AN9: 0 | AO9: 0 | AP9: 0 | AQ9: 0 | AR9: 0 | AW9: 0 | AX9: 0 | AY9: 29 | AZ9: 38 | BA9: 64 | BB9: 216 | BC9: 0 | BD9: 0 | BE9: 0 | BF9: 124 | BG9: 221 | BJ9: 146 | BK9: 1209 | BL9: Current | BM9: https://drive.google.com/open?id=12jXhO0j6hs2AMo30JuNcgMpAiVcS4mkq&usp=drive_fs | BN9: 5" x 8" | BP9: 0 | BQ9: Established | BR9: 3162 | BT9: 28264 | BU9: 0 | BV9: 90 | BW9: 46044 | BX9: 576 | BY9: 543 | BZ9: 12 | CA9: 0 | CB9: 0 | CC9: 0 | CD9: 576 | CE9: 0 | CJ9: 45444 | CK9: 20 | CL9: No | CM9: Established | CN9: Garden | CO9: Seasonal | CP9: 270 | CQ9: 0 | CR9: 84 | CS9: -764 | CT9: 66.7 | CU9: 0 | CV9: 0
A10: Forecast | D10: TPS | E10: Amazon | F10: TPS Plant Foods | G10: 10-10-10 Fertilizer For Trees | H10: 8oz | I10: 0 | J10: 0 | K10: TRIPLE10TREE8OZ | L10: B0D4JFHCPP | M10: F.10-10-10 | N10: 60 | O10: 12x10x12 | P10: LBL-PLANT-003 | Q10: Aptar Pour | R10: Liquid | S10: 75 | T10: 0 | U10: 11.99 | V10: 0 | W10: FALSE | X10: FALSE | Y10: FALSE | Z10: FALSE | AB10: 120 | AC10: 0 | AD10: 0 | AE10: 120 | AF10: 1439 | AH10: 0 | AI10: 59 | AJ10: 816 | AK10: 650 | AL10: 107 | AM10: 2 | AN10: 0 | AO10: 0 | AP10: 0 | AQ10: 0 | AR10: 0 | AW10: 0 | AX10: 0 | AY10: 30 | AZ10: 42 | BA10: 58 | BB10: 200 | BC10: 0 | BD10: 0 | BE10: 0 | BF10: 12 | BG10: 75 | BJ10: 151 | BK10: 59 | BL10: Current | BM10: https://drive.google.com/open?id=12jXhO0j6hs2AMo30JuNcgMpAiVcS4mkq&usp=drive_fs | BN10: 5" x 8" | BP10: 500 | BQ10: Established | BR10: 1162 | BT10: 9784 | BU10: 0 | BV10: 58 | BW10: 46044 | BX10: 540 | BY10: 135 | BZ10: 21 | CA10: 0 | CB10: 120 | CC10: 0 | CD10: 540 | CE10: 0 | CJ10: 45444 | CK10: 20 | CL10: No | CM10: Established | CN10: Garden | CO10: Seasonal | CP10: 100 | CQ10: 0 | CR10: 93 | CS10: -476 | CT10: 66.7 | CU10: 0 | CV10: 0
A11: Forecast | D11: TPS | E11: Amazon | F11: TPS Plant Foods | G11: 10-10-10 Fertilizer For Trees | H11: 1 Gallon | I11: 0 | J11: 0 | K11: TRIPLE10TREE1G | L11: B0D4JKCJP6 | M11: F.10-10-10 | N11: 4 | O11: 13x13x13 | P11: LBL-PLANT-485 | Q11: Berry Unvented | R11: Liquid | S11: 75 | T11: 0 | U11: 49.99 | V11: 0 | W11: FALSE | X11: FALSE | Y11: FALSE | Z11: FALSE | AB11: 68 | AC11: 0 | AD11: 0 | AE11: 32 | AF11: 1600 | AH11: 0 | AI11: 68 | AJ11: 246 | AK11: 555 | AL11: 230 | AM11: 0 | AN11: 0 | AO11: 8 | AP11: 0 | AQ11: 0 | AR11: 0 | AW11: 0 | AX11: 0 | AY11: 11 | AZ11: 13 | BA11: 22 | BB11: 61 | BC11: 0 | BD11: 0 | BE11: 0 | BF11: 0 | BG11: 0 | BJ11: 53 | BK11: 68 | BL11: Current | BM11: https://drive.google.com/open?id=12jXhO0j6hs2AMo30JuNcgMpAiVcS4mkq&usp=drive_fs | BN11: 5" x 8" | BP11: 0 | BQ11: Established | BR11: 1355 | BT11: 12298 | BU11: 0 | BV11: 100 | BW11: 46052 | BX11: 332 | BY11: 102 | BZ11: 8 | CA11: 8 | CB11: 0 | CC11: 4 | CD11: 124 | CE11: 0 | CJ11: 45444 | CK11: 20 | CL11: No | CM11: Established | CN11: Garden | CO11: Seasonal | CP11: 66 | CQ11: 0 | CR11: 29 | CS11: -142 | CT11: 66.7 | CU11: 0 | CV11: 0
A12: Forecast | D12: TPS | E12: Amazon | F12: TPS Plant Foods | G12: 10-10-10 Fertilizer For Vegetables | H12: 8oz | I12: 0 | J12: 0 | K12: TRIPLE10VEG8OZ | L12: B0D4JHN28P | M12: F.10-10-10 | N12: 60 | O12: 12x10x12 | P12: LBL-HV-002 | Q12: Aptar Pour | R12: Liquid | S12: 75 | T12: 0 | U12: 11.99 | V12: 0 | W12: FALSE | X12: FALSE | Y12: FALSE | Z12: FALSE | AB12: 420 | AC12: 0 | AD12: 0 | AE12: 180 | AF12: 2158 | AH12: 0 | AI12: 3070 | AJ12: 469 | AK12: 201 | AL12: 150 | AM12: 0 | AN12: 0 | AO12: 60 | AP12: 0 | AQ12: 0 | AR12: 0 | AW12: 0 | AX12: 0 | AY12: 46 | AZ12: 80 | BA12: 134 | BB12: 353 | BC12: 0 | BD12: 0 | BE12: 0 | BF12: 9 | BG12: 12 | BJ12: 263 | BK12: 3070 | BL12: Current | BM12: https://drive.google.com/open?id=12l6aGFTfM3fx8OCHtThUDBcxxBNlaB_j&usp=drive_fs | BN12: 5" x 8" | BP12: 0 | BQ12: Established | BR12: 2549 | BT12: 5623 | BU12: 0 | BV12: 71 | BW12: 45924 | BX12: 600 | BY12: 350 | BZ12: 18 | CA12: 60 | CB12: 0 | CC12: 0 | CD12: -19 | CE12: 60 | CF12: 19 | CJ12: 45444 | CK12: 20 | CL12: No | CM12: Established | CN12: Garden | CO12: Seasonal | CP12: 366 | CQ12: 0 | CR12: 178 | CS12: 131 | CT12: 66.7 | CU12: 0 | CV12: 0
A13: Forecast | D13: TPS | E13: Amazon | F13: TPS Plant Foods | G13: 10-10-10 Fertilizer For Vegetables | H13: Quart | I13: 0 | J13: 0 | K13: TRIPLE10VEG1Q | L13: B0D4JHJM1R | M13: F.10-10-10 | N13: 12 | O13: 12x10x12 | P13: LBL-PLANT-229 | Q13: Aptar Pour | R13: Liquid | S13: 75 | T13: 0 | U13: 24.99 | V13: 0 | W13: FALSE | X13: FALSE | Y13: FALSE | Z13: FALSE | AB13: 0 | AC13: 0 | AD13: 0 | AE13: 60 | AF13: 1499 | AH13: 0 | AI13: 2021 | AJ13: 231 | AK13: 373 | AL13: 234 | AM13: 7 | AN13: 0 | AO13: 0 | AP13: 0 | AQ13: 0 | AR13: 0 | AW13: 0 | AX13: 0 | AY13: 13 | AZ13: 24 | BA13: 29 | BB13: 84 | BC13: 0 | BD13: 0 | BE13: 0 | BF13: 10 | BG13: 28 | BJ13: 73 | BK13: 2021 | BL13: Current | BM13: https://drive.google.com/open?id=12l6aGFTfM3fx8OCHtThUDBcxxBNlaB_j&usp=drive_fs | BN13: 5" x 8" | BP13: 0 | BQ13: Established | BR13: 5927 | BT13: 5773 | BU13: 0 | BV13: 74 | BW13: 45838 | BX13: 624 | BY13: 145 | BZ13: 2 | CA13: 0 | CB13: 84 | CC13: 0 | CD13: 0 | CE13: 0 | CJ13: 45444 | CK13: 20 | CL13: No | CM13: Established | CN13: Garden | CO13: Seasonal | CP13: 0 | CQ13: 0 | CR13: 53 | CS13: -88 | CT13: 66.7 | CU13: 0 | CV13: 0
A14: Forecast | D14: TPS | E14: Amazon | F14: TPS Plant Foods | G14: 10-10-10 Fertilizer For Vegetables | H14: 1 Gallon | I14: 0 | J14: 0 | K14: TRIPLE10VEG1G | L14: B0D4JGQMQD | M14: F.10-10-10 | N14: 4 | O14: 13x13x13 | P14: LBL-PLANT-486 | Q14: Berry Unvented | R14: Liquid | S14: 75 | T14: 0 | U14: 49.99 | V14: 0 | W14: FALSE | X14: FALSE | Y14: FALSE | Z14: FALSE | AB14: 8 | AC14: 0 | AD14: 0 | AE14: 4 | AF14: 200 | AH14: 0 | AI14: 271 | AJ14: 108 | AK14: 5184 | AL14: 1728 | AM14: 0 | AN14: 0 | AO14: 0 | AP14: 0 | AQ14: 0 | AR14: 0 | AW14: 0 | AX14: 0 | AY14: 0 | AZ14: 1 | BA14: 2 | BB14: 4 | BC14: 0 | BD14: 0 | BE14: 0 | BF14: 0 | BG14: 0 | BJ14: 2 | BK14: 271 | BL14: Current | BM14: https://drive.google.com/open?id=12l6aGFTfM3fx8OCHtThUDBcxxBNlaB_j&usp=drive_fs | BN14: 5" x 8" | BP14: 0 | BQ14: Established | BR14: 22752 | BT14: 5399 | BU14: 0 | BV14: 163 | BW14: 46049 | BX14: 68 | BY14: 36 | BZ14: 4 | CA14: 0 | CB14: 0 | CC14: 0 | CD14: 68 | CE14: 0 | CJ14: 45444 | CK14: 20 | CL14: No | CM14: Established | CN14: Garden | CO14: Seasonal | CP14: 5 | CQ14: 0 | CR14: 2 | CS14: -101 | CT14: 66.7 | CU14: 0 | CV14: 0
A15: Forecast | C15: 45870 | D15: TPS | E15: Amazon | F15: TPS Plant Foods | G15: 4-4-4 Fertilizer | H15: Quart | I15: 0 | J15: 0 | K15: TPS-4-4-4FERT-QUART | L15: B0FKSX9Y7M | M15: F.5-5-5 | N15: 12 | O15: 13x10x10 | P15: LBL-PLANT-230 | Q15: Aptar Pour | R15: Liquid | S15: 75 | T15: 0 | U15: 24.99 | V15: 0 | W15: FALSE | X15: FALSE | Y15: FALSE | Z15: FALSE | AB15: #N/A | AC15: 0 | AD15: 0 | AE15: 48 | AF15: 1200 | AH15: 0 | AI15: 389 | AJ15: 120 | AK15: 216 | AL15: 41 | AM15: 0 | AN15: 0 | AO15: 0 | AP15: 0 | AQ15: 0 | AR15: 0 | AW15: 0 | AX15: 0 | AY15: 17 | AZ15: 17 | BA15: 17 | BB15: 23 | BC15: 0 | BD15: 0 | BE15: 0 | BF15: 0 | BG15: 0 | BJ15: 74 | BK15: 389 | BL15: Current | BM15: https://drive.google.com/file/d/1RSjf9yzQZxBLDGTtNE4k8nJhg0izAVEa/view?usp=drive_link | BN15: 5" x 8" | BP15: 0 | BQ15: 0 | BR15: 2443 | BT15: 2999 | BU15: 0 | BV15: 30 | BW15: 46042 | BY15: 23 | BZ15: 1 | CA15: 0 | CB15: 0 | CC15: 0 | CD15: 96 | CE15: 0 | CJ15: 45870 | CK15: 6 | CM15: #N/A | CN15: Garden | CO15: Seasonal | CP15: #N/A | CR15: 38 | CS15: -81 | CT15: 66.7 | CU15: 0 | CV15: 0
A16: Forecast | C16: 45870 | D16: TPS | E16: Amazon | F16: TPS Plant Foods | G16: 4-4-4 Fertilizer | H16: 1 Gallon | I16: 0 | J16: 0 | K16: TPS-4-4-4FERT-1GALLON | L16: B0FKSBSMW8 | M16: F.5-5-5 | N16: 4 | O16: 13x13x13 | P16: LBL-PLANT-487 | Q16: Berry Unvented | R16: Liquid | S16: 75 | T16: 0 | U16: 39.99 | V16: 0 | W16: FALSE | X16: FALSE | Y16: FALSE | Z16: FALSE | AB16: #N/A | AC16: 0 | AD16: #VALUE! | AE16: 24 | AF16: 960 | AH16: 0 | AI16: 296 | AJ16: 0 | AK16: SOLD OUT | AL16: SOLD OUT | AM16: 0 | AN16: 0 | AO16: 0 | AP16: 0 | AQ16: 0 | AR16: 0 | AW16: 0 | AX16: 0 | AY16: 10 | AZ16: 10 | BA16: 10 | BB16: 10 | BC16: 0 | BD16: 0 | BE16: 0 | BF16: 0 | BG16: 0 | BJ16: 43 | BK16: 296 | BL16: Current | BM16: https://drive.google.com/file/d/1RSjf9yzQZxBLDGTtNE4k8nJhg0izAVEa/view?usp=drive_link | BN16: 5" x 8" | BP16: 0 | BQ16: 0 | BR16: SOLD OUT | BT16: 0 | BU16: 0 | BV16: 0 | BW16: 45946 | BY16: 0 | BZ16: 0 | CA16: 0 | CB16: 0 | CC16: 0 | CD16: 0 | CE16: 0 | CJ16: 45870 | CK16: 6 | CM16: #N/A | CN16: Garden | CO16: Seasonal | CP16: #N/A | CR16: 22 | CS16: 17 | CT16: 66.7 | CU16: 10 | CV16: 0
A17: Forecast | C17: 45870 | D17: TPS | E17: Amazon | F17: TPS Plant Foods | G17: 4-4-4 Fertilizer | H17: 8oz | I17: 0 | J17: 0 | K17: TPS-4-4-4FERT-8OZ | L17: B0FKSCPNVJ | M17: F.5-5-5 | N17: 60 | O17: 12x10x12 | P17: LBL-PLANT-004 | Q17: Aptar Pour | R17: Liquid | S17: 75 | T17: 0 | U17: 11.99 | V17: 0 | W17: FALSE | X17: FALSE | Y17: FALSE | Z17: FALSE | AB17: #N/A | AC17: 0 | AD17: 0 | AE17: 60 | AF17: 719 | AH17: 0 | AI17: 772 | AJ17: 237 | AK17: 1810 | AL17: 428 | AM17: 0 | AN17: 0 | AO17: 1 | AP17: 0 | AQ17: 0 | AR17: 0 | AW17: 0 | AX17: 0 | AY17: 4 | AZ17: 4 | BA17: 4 | BB17: 4 | BC17: 0 | BD17: 0 | BE17: 0 | BF17: 0 | BG17: 0 | BJ17: 17 | BK17: 772 | BL17: Current | BM17: https://drive.google.com/file/d/1RSjf9yzQZxBLDGTtNE4k8nJhg0izAVEa/view?usp=drive_link | BN17: 5" x 8" | BP17: 0 | BQ17: 0 | BR17: 21613 | BT17: 2842 | BU17: 0 | BV17: 89 | BW17: 46041 | BY17: 56 | BZ17: 0 | CA17: 1 | CB17: 0 | CC17: 0 | CD17: 180 | CE17: 0 | CJ17: 45870 | CK17: 6 | CM17: #N/A | CN17: Garden | CO17: Seasonal | CP17: #N/A | CR17: 9 | CS17: -230 | CT17: 66.7 | CU17: 0 | CV17: 0
A18: Forecast | C18: 45870 | D18: TPS | E18: Amazon | F18: TPS Plant Foods | G18: 5-10-10 Fertilizer | H18: Quart | I18: 0 | J18: 0 | K18: TPS-5-10-10FERT-QUART | L18: B0FKT82XBK | M18: F.5-10-10 | N18: 12 | O18: 13x10x10 | P18: LBL-PLANT-231 | Q18: Aptar Pour | R18: Liquid | S18: 75 | T18: 0 | U18: 24.99 | V18: 0 | W18: FALSE | X18: FALSE | Y18: FALSE | Z18: FALSE | AB18: #N/A | AC18: 0 | AD18: 0 | AE18: 72 | AF18: 1799 | AH18: 0 | AI18: 1040 | AJ18: 440 | AK18: 505 | AL18: 15 | AM18: 0 | AN18: 0 | AO18: 0 | AP18: 0 | AQ18: 0 | AR18: 0 | AW18: 0 | AX18: 0 | AY18: 25 | AZ18: 27 | BA18: 31 | BB18: 79 | BC18: 0 | BD18: 0 | BE18: 0 | BF18: 0 | BG18: 0 | BJ18: 112 | BK18: 1040 | BL18: Current | BM18: https://drive.google.com/file/d/1AHwQ4g_70dqAVmkFiUBr8GDQ7L-2_5xS/view?usp=drive_link | BN18: 5" x 8" | BP18: 0 | BQ18: 0 | BR18: 3685 | BT18: 10996 | BU18: 0 | BV18: 24 | BW18: 46050 | BY18: 13 | BZ18: 31 | CA18: 0 | CB18: 0 | CC18: 0 | CD18: 396 | CE18: 0 | CJ18: 45870 | CK18: 6 | CM18: #N/A | CN18: Garden | CO18: Seasonal | CP18: #N/A | CR18: 60 | CS18: -306 | CT18: 66.7 | CU18: 0 | CV18: 0
A19: Forecast | C19: 45870 | D19: TPS | E19: Amazon | F19: TPS Plant Foods | G19: 5-10-10 Fertilizer | H19: 8oz | I19: 0 | J19: 0 | K19: TPS-5-10-10FERT-8OZ | L19: B0FKS8HL6H | M19: F.5-10-10 | N19: 60 | O19: 12x10x12 | P19: LBL-PLANT-005 | Q19: Aptar Pour | R19: Liquid | S19: 75 | T19: 0 | U19: 11.99 | V19: 0 | W19: FALSE | X19: FALSE | Y19: FALSE | Z19: FALSE | AB19: #N/A | AC19: 0 | AD19: 0 | AE19: 60 | AF19: 719 | AH19: 0 | AI19: 476 | AJ19: 152 | AK19: 228 | AL19: 29 | AM19: 0 | AN19: 0 | AO19: 0 | AP19: 0 | AQ19: 0 | AR19: 0 | AW19: 0 | AX19: 0 | AY19: 16 | AZ19: 24 | BA19: 28 | BB19: 68 | BC19: 0 | BD19: 0 | BE19: 0 | BF19: 0 | BG19: 0 | BJ19: 81 | BK19: 476 | BL19: Current | BM19: https://drive.google.com/file/d/1AHwQ4g_70dqAVmkFiUBr8GDQ7L-2_5xS/view?usp=drive_link | BN19: 5" x 8" | BP19: 0 | BQ19: 0 | BR19: 1777 | BT19: 1822 | BU19: 0 | BV19: 14 | BW19: 46051 | BY19: 19 | BZ19: 13 | CA19: 0 | CB19: 0 | CC19: 0 | CD19: 120 | CE19: 0 | CJ19: 45870 | CK19: 6 | CM19: #N/A | CN19: Garden | CO19: Seasonal | CP19: #N/A | CR19: 53 | CS19: -36 | CT19: 66.7 | CU19: 0 | CV19: 0
A20: Forecast | C20: 45870 | D20: TPS | E20: Amazon | F20: TPS Plant Foods | G20: 5-10-10 Fertilizer | H20: 1 Gallon | I20: 0 | J20: 0 | K20: TPS-5-10-10FERT-1GALLON | L20: B0FKSH6N7Y | M20: F.5-10-10 | N20: 4 | O20: 13x13x13 | P20: LBL-PLANT-488 | Q20: Berry Unvented | R20: Liquid | S20: 75 | T20: 0 | U20: 49.99 | V20: 0 | W20: FALSE | X20: FALSE | Y20: FALSE | Z20: FALSE | AB20: #N/A | AC20: 0 | AD20: 0 | AE20: 16 | AF20: 800 | AH20: 0 | AI20: 213 | AJ20: 81 | AK20: 567 | AL20: 224 | AM20: 0 | AN20: 0 | AO20: 0 | AP20: 0 | AQ20: 0 | AR20: 0 | AW20: 0 | AX20: 0 | AY20: 2 | AZ20: 6 | BA20: 9 | BB20: 16 | BC20: 0 | BD20: 0 | BE20: 0 | BF20: 0 | BG20: 0 | BJ20: 15 | BK20: 213 | BL20: Current | BM20: https://drive.google.com/file/d/1AHwQ4g_70dqAVmkFiUBr8GDQ7L-2_5xS/view?usp=drive_link | BN20: 5" x 8" | BP20: 0 | BQ20: 0 | BR20: 3397 | BT20: 4049 | BU20: 0 | BV20: 116 | BW20: 46030 | BY20: 32 | BZ20: 41 | CA20: 0 | CB20: 0 | CC20: 0 | CD20: 0 | CE20: 8 | CJ20: 45870 | CK20: 6 | CM20: #N/A | CN20: Garden | CO20: Seasonal | CP20: #N/A | CR20: 13 | CS20: -54 | CT20: 66.7 | CU20: 0 | CV20: 0
A21: Forecast | C21: 45870 | D21: TPS | E21: Amazon | F21: TPS Plant Foods | G21: 5-10-5 Fertilizer | H21: 8oz | I21: 0 | J21: 0 | K21: TPS-5-10-5FERT-8OZ | L21: B0FKSCB6RH | M21: F.5-10-5 | N21: 60 | O21: 12x10x12 | P21: LBL-PLANT-006 | Q21: Aptar Pour | R21: Liquid | S21: 75 | T21: 0 | U21: 11.99 | V21: 0 | W21: FALSE | X21: FALSE | Y21: FALSE | Z21: FALSE | AB21: #N/A | AC21: 0 | AD21: 0 | AE21: 60 | AF21: 719 | AH21: 0 | AI21: 776 | AJ21: 237 | AK21: 2413 | AL21: 580 | AM21: 0 | AN21: 0 | AO21: 0 | AP21: 0 | AQ21: 0 | AR21: 0 | AW21: 0 | AX21: 0 | AY21: 3 | AZ21: 3 | BA21: 3 | BB21: 6 | BC21: 0 | BD21: 0 | BE21: 0 | BF21: 0 | BG21: 0 | BJ21: 13 | BK21: 776 | BL21: Current | BM21: https://drive.google.com/file/d/11iR9jt_7x6LGPdpyT_QRWjSsvCOJtEJK/view?usp=drive_link | BN21: 5" x 8" | BP21: 0 | BQ21: 0 | BR21: 25333 | BT21: 2842 | BU21: 0 | BV21: 106 | BW21: 46041 | BY21: 57 | BZ21: 0 | CA21: 0 | CB21: 0 | CC21: 0 | CD21: 180 | CE21: 0 | CJ21: 45870 | CK21: 6 | CM21: #N/A | CN21: Garden | CO21: Seasonal | CP21: #N/A | CR21: 7 | CS21: -227 | CT21: 66.7 | CU21: 0 | CV21: 0
A22: Forecast | C22: 45870 | D22: TPS | E22: Amazon | F22: TPS Plant Foods | G22: 5-10-5 Fertilizer | H22: 1 Gallon | I22: 0 | J22: 0 | K22: TPS-5-10-5FERT-1GAL | L22: B0FKSWBYCT | M22: F.5-10-5 | N22: 4 | O22: 13x13x13 | P22: LBL-PLANT-489 | Q22: Berry Unvented | R22: Liquid | S22: 75 | T22: 0 | U22: 49.99 | V22: 0 | W22: FALSE | X22: FALSE | Y22: FALSE | Z22: FALSE | AB22: #N/A | AC22: 0 | AD22: 0 | AE22: 8 | AF22: 400 | AH22: 0 | AI22: 277 | AJ22: 23 | AK22: 483 | AL22: 147 | AM22: 0 | AN22: 0 | AO22: 0 | AP22: 0 | AQ22: 0 | AR22: 0 | AW22: 0 | AX22: 0 | AY22: 1 | AZ22: 2 | BA22: 2 | BB22: 2 | BC22: 0 | BD22: 0 | BE22: 0 | BF22: 0 | BG22: 0 | BJ22: 6 | BK22: 277 | BL22: Current | BM22: https://drive.google.com/file/d/11iR9jt_7x6LGPdpyT_QRWjSsvCOJtEJK/view?usp=drive_link | BN22: 5" x 8" | BP22: 0 | BQ22: 0 | BR22: 12876 | BT22: 1150 | BU22: 0 | BV22: 42 | BW22: 46043 | BY22: 7 | BZ22: 0 | CA22: 0 | CB22: 0 | CC22: 0 | CD22: 16 | CE22: 0 | CF22: 4 | CJ22: 45870 | CK22: 6 | CM22: #N/A | CN22: Garden | CO22: Seasonal | CP22: #N/A | CR22: 4 | CS22: -20 | CT22: 66.7 | CU22: 0 | CV22: 0
A23: Forecast | C23: 45870 | D23: TPS | E23: Amazon | F23: TPS Plant Foods | G23: 5-10-5 Fertilizer | H23: Quart | I23: 0 | J23: 0 | K23: TPS-5-10-5FERT-QUART | L23: B0FKT3R2DS | M23: F.5-10-5 | N23: 12 | O23: 13x10x10 | P23: LBL-PLANT-232 | Q23: Aptar Pour | R23: Liquid | S23: 75 | T23: 0 | U23: 24.99 | V23: 0 | W23: FALSE | X23: FALSE | Y23: FALSE | Z23: FALSE | AB23: #N/A | AC23: 0 | AD23: #VALUE! | AE23: No Sales | AF23: 0 | AH23: 0 | AI23: 388 | AJ23: 132 | AK23: NO SALES | AL23: NO SALES | AM23: 0 | AN23: 0 | AO23: 0 | AP23: 0 | AQ23: 0 | AR23: 0 | AW23: 0 | AX23: 0 | AY23: 0 | AZ23: 0 | BA23: 0 | BB23: 0 | BC23: 0 | BD23: 0 | BE23: 0 | BF23: 0 | BG23: 0 | BJ23: 0 | BK23: 388 | BL23: Current | BM23: https://drive.google.com/file/d/11iR9jt_7x6LGPdpyT_QRWjSsvCOJtEJK/view?usp=drive_link | BN23: 5" x 8" | BP23: 0 | BQ23: 0 | BR23: NO SALES | BT23: 3299 | BU23: 0 | BV23: 127 | BW23: 46042 | BY23: 36 | BZ23: 0 | CA23: 0 | CB23: 0 | CC23: 0 | CD23: 96 | CE23: 0 | CJ23: 45870 | CK23: 6 | CM23: #N/A | CN23: Garden | CO23: Seasonal | CP23: #N/A | CR23: No Sales | CS23: -132 | CT23: 66.7 | CU23: 0 | CV23: 0
A24: Forecast | C24: 45870 | D24: TPS | E24: Amazon | F24: TPS Plant Foods | G24: 5-5-5 Fertilizer | H24: 1 Gallon | I24: 0 | J24: 0 | K24: TPS-5-5-5FERTILIZER-1GAL | L24: B0FKSJ4JG2 | M24: F.5-5-5 | N24: 4 | O24: 13x13x13 | P24: LBL-PLANT-490 | Q24: Berry Unvented | R24: Liquid | S24: 75 | T24: 0 | U24: 39.99 | V24: 0 | W24: FALSE | X24: FALSE | Y24: FALSE | Z24: FALSE | AB24: #N/A | AC24: 0 | AD24: #VALUE! | AE24: No Sales | AF24: 0 | AH24: 0 | AI24: 269 | AJ24: 35 | AK24: NO SALES | AL24: NO SALES | AM24: 0 | AN24: 0 | AO24: 0 | AP24: 0 | AQ24: 0 | AR24: 0 | AW24: 0 | AX24: 0 | AY24: 0 | AZ24: 0 | BA24: 0 | BB24: 0 | BC24: 0 | BD24: 0 | BE24: 0 | BF24: 0 | BG24: 0 | BJ24: 0 | BK24: 269 | BL24: Current | BM24: https://drive.google.com/file/d/1U5eZgvbVmvNkEtQPTQBXJhBjgcU4dOTK/view?usp=drive_link | BN24: 5" x 8" | BP24: 0 | BQ24: #N/A | BR24: NO SALES | BT24: 1400 | BU24: 0 | BV24: 119 | BW24: 46043 | BY24: 11 | BZ24: 0 | CA24: 0 | CB24: 0 | CC24: 0 | CD24: 24 | CE24: 0 | CJ24: 45870 | CK24: 6 | CM24: #N/A | CN24: Garden | CO24: Seasonal | CP24: #N/A | CR24: No Sales | CS24: -35 | CT24: 66.7 | CU24: 0 | CV24: 0
A25: Forecast | C25: 45870 | D25: TPS | E25: Amazon | F25: TPS Plant Foods | G25: 5-5-5 fertilizer | H25: 8oz | I25: 0 | J25: 0 | K25: TPS-5-5-5FERTILIZER-8OZ | L25: B0FKSWG5VR | M25: F.5-5-5 | N25: 60 | O25: 12x10x12 | P25: LBL-PLANT-007 | Q25: Aptar Pour | R25: Liquid | S25: 75 | T25: 0 | U25: 11.99 | V25: 0 | W25: FALSE | X25: FALSE | Y25: FALSE | Z25: FALSE | AB25: #N/A | AC25: 0 | AD25: #VALUE! | AE25: No Sales | AF25: 0 | AH25: 0 | AI25: 820 | AJ25: 219 | AK25: NO SALES | AL25: NO SALES | AM25: 0 | AN25: 0 | AO25: 0 | AP25: 0 | AQ25: 0 | AR25: 0 | AW25: 0 | AX25: 0 | AY25: 0 | AZ25: 0 | BA25: 0 | BB25: 0 | BC25: 0 | BD25: 0 | BE25: 0 | BF25: 0 | BG25: 0 | BJ25: 0 | BK25: 820 | BL25: Current | BM25: https://drive.google.com/file/d/1U5eZgvbVmvNkEtQPTQBXJhBjgcU4dOTK/view?usp=drive_link | BN25: 5" x 8" | BP25: 0 | BQ25: #N/A | BR25: NO SALES | BT25: 2626 | BU25: 0 | BV25: 42 | BW25: 46041 | BY25: 32 | BZ25: 7 | CA25: 0 | CB25: 0 | CC25: 0 | CD25: 180 | CE25: 0 | CJ25: 45870 | CK25: 6 | CM25: #N/A | CN25: Garden | CO25: Seasonal | CP25: #N/A | CR25: No Sales | CS25: -219 | CT25: 66.7 | CU25: 0 | CV25: 0
A26: Forecast | C26: 45870 | D26: TPS | E26: Amazon | F26: TPS Plant Foods | G26: 5-5-5 fertilizer | H26: Quart | I26: 0 | J26: 0 | K26: TPS-5-5-5FERTILIZER-QUART | L26: B0FKS85TJP | M26: F.5-5-5 | N26: 12 | O26: 13x10x10 | P26: LBL-PLANT-233 | Q26: Aptar Pour | R26: Liquid | S26: 75 | T26: 0 | U26: 24.99 | V26: 0 | W26: FALSE | X26: FALSE | Y26: FALSE | Z26: FALSE | AB26: #N/A | AC26: 0 | AD26: #VALUE! | AE26: No Sales | AF26: 0 | AH26: 0 | AI26: 443 | AJ26: 72 | AK26: NO SALES | AL26: NO SALES | AM26: 0 | AN26: 0 | AO26: 0 | AP26: 0 | AQ26: 0 | AR26: 0 | AW26: 0 | AX26: 0 | AY26: 0 | AZ26: 0 | BA26: 0 | BB26: 0 | BC26: 0 | BD26: 0 | BE26: 0 | BF26: 0 | BG26: 0 | BJ26: 0 | BK26: 443 | BL26: Current | BM26: https://drive.google.com/file/d/1U5eZgvbVmvNkEtQPTQBXJhBjgcU4dOTK/view?usp=drive_link | BN26: 5" x 8" | BP26: 0 | BQ26: #N/A | BR26: NO SALES | BT26: 1799 | BU26: 0 | BV26: 135 | BW26: 46042 | BY26: 24 | BZ26: 0 | CA26: 0 | CB26: 0 | CC26: 0 | CD26: 48 | CE26: 0 | CJ26: 45870 | CK26: 6 | CM26: #N/A | CN26: Garden | CO26: Seasonal | CP26: #N/A | CR26: No Sales | CS26: -72 | CT26: 66.7 | CU26: 0 | CV26: 0
A27: Forecast | C27: 45870 | D27: TPS | E27: Amazon | F27: TPS Plant Foods | G27: 7-7-7 Fertilizer | H27: 1 Gallon | I27: 0 | J27: 0 | K27: TPS-7-7-7FERT-1GALLON | L27: B0FKSL8XQ8 | M27: F.8-8-8 | N27: 4 | O27: 13x13x13 | P27: LBL-PLANT-491 | Q27: Berry Unvented | R27: Liquid | S27: 75 | T27: 0 | U27: 49.99 | V27: 0 | W27: FALSE | X27: FALSE | Y27: FALSE | Z27: FALSE | AB27: #N/A | AC27: 0 | AD27: 0 | AE27: 4 | AF27: 200 | AH27: 0 | AI27: 208 | AJ27: 90 | AK27: 1779 | AL27: 296 | AM27: 0 | AN27: 0 | AO27: 0 | AP27: 0 | AQ27: 0 | AR27: 0 | AW27: 0 | AX27: 0 | AY27: 1 | AZ27: 1 | BA27: 4 | BB27: 6 | BC27: 0 | BD27: 0 | BE27: 0 | BF27: 0 | BG27: 0 | BJ27: 5 | BK27: 208 | BL27: Current | BM27: https://drive.google.com/file/d/1WbNtYLKkm39rDwsFYF4rPeGhz3VDyFt8/view?usp=drive_link | BN27: 5" x 8" | BP27: 0 | BQ27: 0 | BR27: 14923 | BT27: 4499 | BU27: 0 | BV27: 241 | BW27: 46042 | BY27: 15 | BZ27: 39 | CA27: 0 | CB27: 0 | CC27: 0 | CD27: 36 | CE27: 0 | CJ27: 45870 | CK27: 6 | CM27: #N/A | CN27: Garden | CO27: Seasonal | CP27: #N/A | CR27: 2 | CS27: -80 | CT27: 66.7 | CU27: 0 | CV27: 0
A28: Forecast | C28: 45870 | D28: TPS | E28: Amazon | F28: TPS Plant Foods | G28: 7-7-7 Fertilizer | H28: 8oz | I28: 0 | J28: 0 | K28: TPS-7-7-7FERT-8OZ | L28: B0FKSFPF2R | M28: F.8-8-8 | N28: 60 | O28: 12x10x12 | P28: LBL-PLANT-008 | Q28: Aptar Pour | R28: Liquid | S28: 75 | T28: 0 | U28: 11.99 | V28: 0 | W28: FALSE | X28: FALSE | Y28: FALSE | Z28: FALSE | AB28: #N/A | AC28: 0 | AD28: #VALUE! | AE28: No Sales | AF28: 0 | AH28: 0 | AI28: 782 | AJ28: 240 | AK28: NO SALES | AL28: NO SALES | AM28: 0 | AN28: 0 | AO28: 0 | AP28: 0 | AQ28: 0 | AR28: 0 | AW28: 0 | AX28: 0 | AY28: 0 | AZ28: 0 | BA28: 0 | BB28: 0 | BC28: 0 | BD28: 0 | BE28: 0 | BF28: 0 | BG28: 0 | BJ28: 0 | BK28: 782 | BL28: Current | BM28: https://drive.google.com/file/d/1WbNtYLKkm39rDwsFYF4rPeGhz3VDyFt8/view?usp=drive_link | BN28: 5" x 8" | BP28: 0 | BQ28: 0 | BR28: NO SALES | BT28: 2878 | BU28: 0 | BV28: 0 | BW28: 46041 | BY28: 60 | BZ28: 0 | CA28: 0 | CB28: 0 | CC28: 0 | CD28: 180 | CE28: 0 | CJ28: 45870 | CK28: 6 | CM28: #N/A | CN28: Garden | CO28: Seasonal | CP28: #N/A | CR28: No Sales | CS28: -240 | CT28: 66.7 | CU28: 0 | CV28: 0
A29: Forecast | C29: 45870 | D29: TPS | E29: Amazon | F29: TPS Plant Foods | G29: 7-7-7 Fertilizer | H29: Quart | I29: 0 | J29: 0 | K29: TPS-7-7-7FERT-QUART | L29: B0FKT3RRQ2 | M29: F.8-8-8 | N29: 12 | O29: 13x10x10 | P29: LBL-PLANT-234 | Q29: Aptar Pour | R29: Liquid | S29: 75 | T29: 0 | U29: 24.99 | V29: 0 | W29: FALSE | X29: FALSE | Y29: FALSE | Z29: FALSE | AB29: #N/A | AC29: 0 | AD29: #VALUE! | AE29: No Sales | AF29: 0 | AH29: 0 | AI29: 435 | AJ29: 84 | AK29: NO SALES | AL29: NO SALES | AM29: 0 | AN29: 0 | AO29: 0 | AP29: 0 | AQ29: 0 | AR29: 0 | AW29: 0 | AX29: 0 | AY29: 0 | AZ29: 0 | BA29: 0 | BB29: 0 | BC29: 0 | BD29: 0 | BE29: 0 | BF29: 0 | BG29: 0 | BJ29: 0 | BK29: 435 | BL29: Current | BM29: https://drive.google.com/file/d/1WbNtYLKkm39rDwsFYF4rPeGhz3VDyFt8/view?usp=drive_link | BN29: 5" x 8" | BP29: 0 | BQ29: 0 | BR29: NO SALES | BT29: 2099 | BU29: 0 | BV29: 0 | BW29: 46042 | BY29: 36 | BZ29: 0 | CA29: 0 | CB29: 0 | CC29: 0 | CD29: 48 | CE29: 0 | CJ29: 45870 | CK29: 6 | CM29: #N/A | CN29: Garden | CO29: Seasonal | CP29: #N/A | CR29: No Sales | CS29: -84 | CT29: 66.7 | CU29: 0 | CV29: 0
A30: Forecast | C30: 45870 | D30: TPS | E30: Amazon | F30: TPS Plant Foods | G30: 8-8-8 fertilizer | H30: Quart | I30: 0 | J30: 0 | K30: TPS-8-8-8FERT-QUART | L30: B0FKSYTZBJ | M30: F.8-8-8 | N30: 12 | O30: 13x10x10 | P30: LBL-PLANT-235 | Q30: Aptar Pour | R30: Liquid | S30: 75 | T30: 0 | U30: 24.99 | V30: 0 | W30: FALSE | X30: FALSE | Y30: FALSE | Z30: FALSE | AB30: #N/A | AC30: 0 | AD30: 0 | AE30: No Sales | AF30: 0 | AH30: 0 | AI30: 391 | AJ30: 131 | AK30: 22008 | AL30: 5880 | AM30: 0 | AN30: 0 | AO30: 0 | AP30: 0 | AQ30: 0 | AR30: 0 | AW30: 0 | AX30: 0 | AY30: 0 | AZ30: 0 | BA30: 1 | BB30: 1 | BC30: 0 | BD30: 0 | BE30: 0 | BF30: 0 | BG30: 0 | BJ30: 0 | BK30: 391 | BL30: Current | BM30: https://drive.google.com/file/d/1bKMPptO4VQdWhMYrdyvZ5jQqzJtIcs9T/view?usp=drive_link | BN30: 5" x 8" | BP30: 0 | BQ30: 0 | BR30: 313333 | BT30: 3274 | BU30: 0 | BV30: 127 | BW30: 46042 | BY30: 35 | BZ30: 0 | CA30: 0 | CB30: 0 | CC30: 0 | CD30: 96 | CE30: 0 | CJ30: 45870 | CK30: 6 | CM30: #N/A | CN30: Garden | CO30: Seasonal | CP30: #N/A | CR30: No Sales | CS30: -129 | CT30: 66.7 | CU30: 0 | CV30: 0
A31: Forecast | C31: 45870 | D31: TPS | E31: Amazon | F31: TPS Plant Foods | G31: 8-8-8 fertilizer | H31: 1 Gallon | I31: 0 | J31: 0 | K31: TPS-8-8-8FERT-1GALLON | L31: B0FKSFH249 | M31: F.8-8-8 | N31: 4 | O31: 13x13x13 | P31: LBL-PLANT-492 | Q31: Berry Unvented | R31: Liquid | S31: 75 | T31: 0 | U31: 49.99 | V31: 0 | W31: FALSE | X31: FALSE | Y31: FALSE | Z31: FALSE | AB31: #N/A | AC31: 0 | AD31: #VALUE! | AE31: No Sales | AF31: 0 | AH31: 0 | AI31: 293 | AJ31: 12 | AK31: NO SALES | AL31: NO SALES | AM31: 0 | AN31: 0 | AO31: 0 | AP31: 0 | AQ31: 0 | AR31: 0 | AW31: 0 | AX31: 0 | AY31: 0 | AZ31: 0 | BA31: 0 | BB31: 0 | BC31: 0 | BD31: 0 | BE31: 0 | BF31: 0 | BG31: 0 | BJ31: 0 | BK31: 293 | BL31: Current | BM31: https://drive.google.com/file/d/1bKMPptO4VQdWhMYrdyvZ5jQqzJtIcs9T/view?usp=drive_link | BN31: 5" x 8" | BP31: 0 | BQ31: 0 | BR31: NO SALES | BT31: 600 | BU31: 0 | BV31: 0 | BW31: 45946 | BY31: 12 | BZ31: 0 | CA31: 0 | CB31: 0 | CC31: 0 | CD31: 0 | CE31: 0 | CJ31: 45870 | CK31: 6 | CM31: #N/A | CN31: Garden | CO31: Seasonal | CP31: #N/A | CR31: No Sales | CS31: -12 | CT31: 66.7 | CU31: 0 | CV31: 0
A32: Forecast | C32: 45870 | D32: TPS | E32: Amazon | F32: TPS Plant Foods | G32: 8-8-8 fertilizer | H32: 8oz | I32: 0 | J32: 0 | K32: TPS-8-8-8FERT-8OZ | L32: B0FKS81ZNW | M32: F.8-8-8 | N32: 60 | O32: 12x10x12 | P32: LBL-PLANT-009 | Q32: Aptar Pour | R32: Liquid | S32: 75 | T32: 0 | U32: 11.99 | V32: 0 | W32: FALSE | X32: FALSE | Y32: FALSE | Z32: FALSE | AB32: #N/A | AC32: 0 | AD32: #VALUE! | AE32: No Sales | AF32: 0 | AH32: 0 | AI32: 777 | AJ32: 240 | AK32: NO SALES | AL32: NO SALES | AM32: 0 | AN32: 0 | AO32: 0 | AP32: 0 | AQ32: 0 | AR32: 0 | AW32: 0 | AX32: 0 | AY32: 0 | AZ32: 0 | BA32: 0 | BB32: 0 | BC32: 0 | BD32: 0 | BE32: 0 | BF32: 0 | BG32: 0 | BJ32: 0 | BK32: 777 | BL32: Current | BM32: https://drive.google.com/file/d/1bKMPptO4VQdWhMYrdyvZ5jQqzJtIcs9T/view?usp=drive_link | BN32: 5" x 8" | BP32: 0 | BQ32: 0 | BR32: NO SALES | BT32: 2878 | BU32: 0 | BV32: 136 | BW32: 46041 | BY32: 60 | BZ32: 0 | CA32: 0 | CB32: 0 | CC32: 0 | CD32: 180 | CE32: 0 | CJ32: 45870 | CK32: 6 | CM32: #N/A | CN32: Garden | CO32: Seasonal | CP32: #N/A | CR32: No Sales | CS32: -240 | CT32: 66.7 | CU32: 0 | CV32: 0
A33: Forecast | D33: TPS | E33: Amazon | F33: Bloom City | G33: Acid Loving Plants | H33: Quart | I33: 0 | J33: 0 | K33: BACIDLOVING1Q-0224 | L33: B0C4ZW6QQP | M33: F.Tomato Veggie | N33: 12 | O33: 13x13x10 | P33: LBL-PLANT-464 | Q33: VENTED Berry | R33: Liquid | S33: 150 | T33: 0 | U33: 24.99 | V33: 0 | W33: FALSE | X33: FALSE | Y33: FALSE | Z33: FALSE | AB33: 0 | AC33: 0 | AD33: 0 | AE33: 96 | AF33: 2399 | AH33: 0 | AI33: 1196 | AJ33: 361 | AK33: 292 | AL33: 100 | AM33: 17 | AN33: 0 | AO33: 0 | AP33: 0 | AQ33: 0 | AR33: 0 | AW33: 0 | AX33: 0 | AY33: 29 | AZ33: 42 | BA33: 58 | BB33: 202 | BC33: 152 | BD33: 50 | BE33: 105 | BF33: 321 | BG33: 232 | BJ33: 148 | BK33: 1196 | BL33: Current | BM33: https://drive.google.com/open?id=1v8Pdw5RZxgLrNWi4jukYeYf-w9BAkKxh&usp=drive_fs | BN33: 5" x 8" | BP33: 0 | BQ33: Established | BR33: 2058 | BT33: 9021 | BU33: 0 | BV33: 45 | BW33: 45875 | BX33: 720 | BY33: 124 | BZ33: 33 | CA33: 0 | CB33: 204 | CC33: 0 | CD33: 0 | CE33: 0 | CJ33: 45108 | CK33: 31 | CL33: No | CM33: Established | CN33: Garden | CO33: Seasonal | CP33: 0 | CQ33: 0 | CR33: 93 | CS33: -147 | CT33: 66.7 | CU33: 0 | CV33: 0
A34: Forecast | D34: TPS | E34: Amazon | F34: Bloom City | G34: Acid Loving Plants | H34: 1 Gallon | I34: 0 | J34: 0 | K34: BACIDLOVING1G-0224 | L34: B0BZB814JM | M34: F.Tomato Veggie | N34: 4 | O34: 13x13x13 | P34: LBL-PLANT-641 | Q34: VENTED Berry | R34: Liquid | S34: 150 | T34: 0 | V34: 0 | W34: FALSE | X34: FALSE | Y34: FALSE | Z34: FALSE | AB34: 0 | AC34: 0 | AD34: 0 | AE34: 16 | AF34: 0 | AH34: 0 | AI34: 469 | AJ34: 123 | AK34: 498 | AL34: 117 | AM34: 18 | AN34: 0 | AO34: 8 | AP34: 0 | AQ34: 0 | AR34: 0 | AW34: 0 | AX34: 0 | AY34: 6 | AZ34: 7 | BA34: 13 | BB34: 27 | BC34: 26 | BD34: 15 | BE34: 28 | BF34: 49 | BG34: 42 | BJ34: 29 | BK34: 469 | BL34: Current | BM34: https://drive.google.com/open?id=1v8Pdw5RZxgLrNWi4jukYeYf-w9BAkKxh&usp=drive_fs | BN34: 5" x 8" | BP34: 0 | BQ34: Established | BR34: 5150 | BT34: 0 | BU34: 0 | BV34: 0 | BW34: 45974 | BX34: 100 | BY34: 29 | BZ34: 6 | CA34: 8 | CB34: 72 | CC34: 0 | CD34: 0 | CE34: 8 | CJ34: 45108 | CK34: 31 | CL34: Yes | CM34: Established | CN34: Garden | CO34: Seasonal | CP34: 0 | CQ34: 0 | CR34: 16 | CS34: -90 | CT34: 66.7 | CU34: 0 | CV34: 0
A35: Forecast | C35: 45870 | D35: TPS | E35: Amazon | F35: TPS Plant Foods | G35: Acidic Fertilizer | H35: 8oz | I35: 0 | J35: 0 | K35: TPS-ACIDICFERT-8OZ | L35: B0FKSZ2261 | M35: F.Ultra Bloom | N35: 60 | O35: 12x10x12 | P35: LBL-PLANT-010 | Q35: Aptar Pour | R35: Liquid | S35: 75 | T35: 0 | U35: 11.99 | V35: 0 | W35: FALSE | X35: FALSE | Y35: FALSE | Z35: FALSE | AB35: #N/A | AC35: 0 | AD35: #VALUE! | AE35: 120 | AF35: 1439 | AH35: 0 | AI35: 419 | AJ35: 540 | AK35: 965 | AL35: SOLD OUT | AM35: 0 | AN35: 0 | AO35: 0 | AP35: 0 | AQ35: 0 | AR35: 0 | AW35: 0 | AX35: 0 | AY35: 1 | AZ35: 34 | BA35: 40 | BB35: 50 | BC35: 0 | BD35: 0 | BE35: 0 | BF35: 0 | BG35: 0 | BJ35: 50 | BK35: 419 | BL35: Current | BM35: https://drive.google.com/file/d/1Of2Tz3LkTV8WqEEZR0Q9VnsT5pGWqsSf/view?usp=drive_link | BN35: 5" x 8" | BP35: 0 | BQ35: 0 | BR35: 2266 | BT35: 6475 | BU35: 0 | BV35: 0 | BW35: 46048 | BY35: 0 | BZ35: 0 | CA35: 0 | CB35: 0 | CC35: 0 | CD35: 540 | CE35: 0 | CJ35: 45870 | CK35: 6 | CM35: #N/A | CN35: Garden | CO35: Seasonal | CP35: #N/A | CR35: 76 | CS35: -455 | CT35: 66.7 | CU35: 0 | CV35: 0
A36: Forecast | C36: 45870 | D36: TPS | E36: Amazon | F36: TPS Plant Foods | G36: Acidic Fertilizer | H36: 1 Gallon | I36: 0 | J36: 0 | K36: TPS-ACIDICFERT-1GALLON | L36: B0FKSQK91K | M36: F.Ultra Bloom | N36: 4 | O36: 13x13x13 | P36: LBL-PLANT-493 | Q36: Berry Unvented | R36: Liquid | S36: 75 | T36: 0 | U36: 49.99 | V36: 0 | W36: FALSE | X36: FALSE | Y36: FALSE | Z36: FALSE | AB36: #N/A | AC36: 0 | AD36: 0 | AE36: 4 | AF36: 200 | AH36: 0 | AI36: 176 | AJ36: 53 | AK36: 1619 | AL36: 275 | AM36: 0 | AN36: 0 | AO36: -4 | AP36: 0 | AQ36: 0 | AR36: 0 | AW36: 0 | AX36: 0 | AY36: 1 | AZ36: 1 | BA36: 1 | BB36: 3 | BC36: 0 | BD36: 0 | BE36: 0 | BF36: 0 | BG36: 0 | BJ36: 4 | BK36: 176 | BL36: Current | BM36: https://drive.google.com/file/d/1Of2Tz3LkTV8WqEEZR0Q9VnsT5pGWqsSf/view?usp=drive_link | BN36: 5" x 8" | BP36: 0 | BQ36: 0 | BR36: 15282 | BT36: 2649 | BU36: 0 | BV36: 95 | BW36: 46049 | BY36: 9 | BZ36: 0 | CA36: -4 | CB36: 0 | CC36: 0 | CD36: 48 | CE36: 0 | CG36: 4 | CJ36: 45870 | CK36: 6 | CM36: #N/A | CN36: Garden | CO36: Seasonal | CP36: #N/A | CR36: 2 | CS36: -48 | CT36: 66.7 | CU36: 0 | CV36: 0
A37: Forecast | C37: 45870 | D37: TPS | E37: Amazon | F37: TPS Plant Foods | G37: Acidic Fertilizer | H37: Quart | I37: 0 | J37: 0 | K37: TPS-ACIDICFERT-QUART | L37: B0FKSSDRX9 | M37: F.Ultra Bloom | N37: 12 | O37: 13x10x10 | P37: LBL-PLANT-236 | Q37: Aptar Pour | R37: Liquid | S37: 75 | T37: 0 | U37: 24.99 | V37: 0 | W37: FALSE | X37: FALSE | Y37: FALSE | Z37: FALSE | AB37: #N/A | AC37: 0 | AD37: 0 | AE37: 12 | AF37: 300 | AH37: 0 | AI37: 469 | AJ37: 18 | AK37: 1210 | AL37: 1210 | AM37: 0 | AN37: 0 | AO37: 0 | AP37: 0 | AQ37: 0 | AR37: 0 | AW37: 0 | AX37: 0 | AY37: 0 | AZ37: 1 | BA37: 1 | BB37: 2 | BC37: 0 | BD37: 0 | BE37: 0 | BF37: 0 | BG37: 0 | BJ37: 1 | BK37: 469 | BL37: Current | BM37: https://drive.google.com/file/d/1Of2Tz3LkTV8WqEEZR0Q9VnsT5pGWqsSf/view?usp=drive_link | BN37: 5" x 8" | BP37: 0 | BQ37: 0 | BR37: 36542 | BT37: 450 | BU37: 0 | BV37: 164 | BW37: 45875 | BY37: 18 | BZ37: 0 | CA37: 0 | CB37: 0 | CC37: 0 | CD37: 0 | CE37: 0 | CJ37: 45870 | CK37: 6 | CM37: #N/A | CN37: Garden | CO37: Seasonal | CP37: #N/A | CR37: 2 | CS37: -15 | CT37: 66.7 | CU37: 0 | CV37: 0
A38: Forecast | D38: TPS | E38: Amazon | F38: TPS Plant Foods | G38: African Violet Fertilizer | H38: 8oz | I38: 0 | J38: 0 | K38: AFVIOLET8OZ-FBA-UPC-0523 | L38: B0C73TS2P2 | M38: F.Succulent | N38: 60 | O38: 12x10x12 | P38: LBL-PLANT-011 | Q38: Aptar Pour | R38: Liquid | S38: 75 | T38: 0 | U38: 11.99 | V38: 0 | W38: FALSE | X38: FALSE | Y38: FALSE | Z38: FALSE | AB38: 720 | AC38: 0 | AD38: 0 | AE38: 300 | AF38: 3597 | AH38: 0 | AI38: 302 | AJ38: 1551 | AK38: 363 | AL38: 61 | AM38: 0 | AN38: 0 | AO38: 120 | AP38: 0 | AQ38: 0 | AR38: 0 | AW38: 0 | AX38: 0 | AY38: 97 | AZ38: 140 | BA38: 217 | BB38: 615 | BC38: 576 | BD38: 695 | BE38: 899 | BF38: 1057 | BG38: 1051 | BJ38: 503 | BK38: 302 | BL38: Critical Changes Made | BM38: https://drive.google.com/open?id=1JnGu0H9zRaRnzreYoWN4Wp78L8BT6Z4o&usp=drive_fs | BN38: 5" x 8" | BP38: 0 | BQ38: Established | BR38: 764 | BT38: 18596 | BU38: 0 | BV38: 56 | BW38: 46034 | BX38: 1080 | BY38: 259 | BZ38: 32 | CA38: 120 | CB38: 0 | CC38: 60 | CD38: 1080 | CE38: 0 | CJ38: 45108 | CK38: 31 | CL38: No | CM38: Established | CN38: Houseplant | CO38: Flat | CP38: 719 | CQ38: 0 | CR38: 275 | CS38: -254 | CT38: 59 | CU38: 0 | CV38: 0
A39: Forecast | D39: TPS | E39: Amazon | F39: TPS Plant Foods | G39: African Violet Fertilizer | H39: Quart | I39: 0 | J39: 0 | K39: AFVIOLET1Q-FBA-UPC-0523 | L39: B0C73RC4V9 | M39: F.Succulent | N39: 12 | O39: 13x13x10 | P39: LBL-PLANT-237 | Q39: Aptar Pour | R39: Liquid | S39: 75 | T39: 0 | U39: 24.99 | V39: 0 | W39: FALSE | X39: FALSE | Y39: FALSE | Z39: FALSE | AB39: 0 | AC39: 0 | AD39: 0 | AE39: 12 | AF39: 300 | AH39: 0 | AI39: 959 | AJ39: 196 | AK39: 1291 | AL39: 488 | AM39: 10 | AN39: 0 | AO39: 0 | AP39: 0 | AQ39: 0 | AR39: 0 | AW39: 0 | AX39: 0 | AY39: 4 | AZ39: 5 | BA39: 6 | BB39: 31 | BC39: 89 | BD39: 87 | BE39: 33 | BF39: 22 | BG39: 39 | BJ39: 19 | BK39: 959 | BL39: Critical Changes Made | BM39: https://drive.google.com/open?id=1JnGu0H9zRaRnzreYoWN4Wp78L8BT6Z4o&usp=drive_fs | BN39: 5" x 8" | BP39: 0 | BQ39: Established | BR39: 11363 | BT39: 4898 | BU39: 0 | BV39: 0 | BY39: 74 | BZ39: 2 | CA39: 0 | CB39: 120 | CC39: 0 | CD39: 0 | CE39: 0 | CJ39: 45108 | CK39: 31 | CL39: No | CM39: Established | CN39: Houseplant | CO39: Flat | CP39: 0 | CQ39: 0 | CR39: 10 | CS39: -180 | CT39: 59 | CU39: 0 | CV39: 0
A40: Forecast | D40: TPS | E40: Amazon | F40: TPS Plant Foods | G40: African Violet Fertilizer | H40: 1 Gallon | I40: 0 | J40: 0 | K40: AFVIOLET1G-FBA-UPC-0523 | L40: B0C73TDLPX | M40: F.Succulent | N40: 4 | O40: 13x13x13 | P40: LBL-PLANT-494 | Q40: Berry Unvented | R40: Liquid | S40: 75 | T40: 0 | U40: 59.99 | V40: 0 | W40: FALSE | X40: FALSE | Y40: FALSE | Z40: FALSE | AB40: 4 | AC40: 0 | AD40: #DIV/0! | AE40: No Sales | AF40: 0 | AH40: 0 | AI40: 245 | AJ40: 10 | AK40: NO SALES | AL40: #DIV/0! | AM40: 0 | AN40: #DIV/0! | AO40: 0 | AP40: 0 | AQ40: 0 | AR40: 0 | AW40: 0 | AX40: 0 | AY40: 0 | AZ40: 0 | BA40: 0 | BB40: 1 | BC40: 5 | BD40: 0 | BE40: 2 | BF40: 1 | BG40: 1 | BJ40: 0 | BK40: 245 | BL40: Critical Changes Made | BM40: https://drive.google.com/open?id=1JnGu0H9zRaRnzreYoWN4Wp78L8BT6Z4o&usp=drive_fs | BN40: 5" x 8" | BP40: 0 | BQ40: Established | BR40: 153176 | BT40: 600 | BU40: 0 | BV40: 0 | BW40: 45945 | BX40: 12 | BY40: 10 | BZ40: 0 | CA40: 0 | CB40: 0 | CC40: 0 | CD40: 0 | CE40: 0 | CJ40: 45108 | CK40: 31 | CL40: No | CM40: Established | CN40: Houseplant | CO40: Flat | CP40: 1 | CQ40: 0 | CR40: No Sales | CS40: -9 | CT40: 59 | CU40: 0 | CV40: 0
...
